Workbook

Sheet Read me
A1: Materials review — rename, keep, cut, missing
A2: Generated 2026-10-07 from the shipped catalog: 1554 materials, plus 125 new rows waiting to be added.
A4: HOW TO MARK IT — only the YELLOW columns are yours to type in.
A5: 1. Review tab: the Decision column is already filled in. Most rows need nothing from you. Change it only where you disagree.
A6: Keep proposed = take the new name shown. Keep = keep today's name. Rename = type your own name in 'Your name'.
A7: Cut = we stop shipping it. Add = a new row goes into the catalog. Your call = an open question decides it — pick one.
A8: 2. Missing tab: things the catalog lacks. 'Typical job' rows are pre-filled Add (change to Skip if not wanted); size gaps and starter parts are blank — mark Add or Skip. Add your own rows at the bottom.
A9: 3. Possible duplicates tab: pairs that look like one part under two names. Pick Same - keep A, Same - keep B, or Not the same.
A10: 'Same - keep A' cuts B; anything that used B (a starter assembly, a run type) is moved to A. Bids already priced keep what they have.
A11: 4. Questions tab: five naming questions, each with our recommendation. Answer each one.
A12: 5. Counts tab: totals as you mark, and the warnings that must be 0 before the names can freeze.
A14: WHAT A CUT DOES: the material disappears from every list and search. Bids that already use it keep it, unchanged. Nothing is deleted.
... A21: Not on this sheet: the 519 brand variants for panels and breakers — their own pass, after the names freeze.

Sheet Review
A1: # | B1: Category | C1: Type | D1: Current name | E1: Proposed name | F1: Why | G1: Used by | H1: Status | I1: Decision | J1: Your name | K1: Note | L1: Final name (follows your marks) | M1: Check | N1: Uses | O1: Question
A2: 1 | B2: Wire & Cable | C2: bare CU, solid | D2: #14 bare CU, solid | E2: #14 bare solid Copper | F2: wire rule: size/type, metal spelled out at the end | G2: — | H2: Shipped | I2: Keep proposed | L2: =IF(I2="Cut","",IF(I2="Your call","(decide)",IF(I2="Rename",J2,IF(I2="Keep",IF(D2="",E2,D2),IF(E2="(unchanged)",D2,E2))))) | M2: =IF(AND(I2="Cut",N2>0,K2=""),"USED: say what replaces it (Note)",IF(AND(I2="Rename",J2=""),"type the new name",IF(AND(L2<>"",L2<>"(decide)",COUNTIF($L$2:$L$1680,L2)>1),"SAME FINAL NAME AS ANOTHER ROW",""))) | N2: 0
A3: 2 | B3: Wire & Cable | C3: bare CU, solid | D3: #12 bare CU, solid | E3: #12 bare solid Copper | F3: wire rule: size/type, metal spelled out at the end | G3: 2 run types | H3: Shipped | I3: Keep proposed | L3: =IF(I3="Cut","",IF(I3="Your call","(decide)",IF(I3="Rename",J3,IF(I3="Keep",IF(D3="",E3,D3),IF(E3="(unchanged)",D3,E3))))) | M3: =IF(AND(I3="Cut",N3>0,K3=""),"USED: say what replaces it (Note)",IF(AND(I3="Rename",J3=""),"type the new name",IF(AND(L3<>"",L3<>"(decide)",COUNTIF($L$2:$L$1680,L3)>1),"SAME FINAL NAME AS ANOTHER ROW",""))) | N3: 2
A4: 3 | B4: Wire & Cable | C4: bare CU, solid | D4: #10 bare CU, solid | E4: #10 bare solid Copper | F4: wire rule: size/type, metal spelled out at the end | G4: — | H4: Shipped | I4: Keep proposed | L4: =IF(I4="Cut","",IF(I4="Your call","(decide)",IF(I4="Rename",J4,IF(I4="Keep",IF(D4="",E4,D4),IF(E4="(unchanged)",D4,E4))))) | M4: =IF(AND(I4="Cut",N4>0,K4=""),"USED: say what replaces it (Note)",IF(AND(I4="Rename",J4=""),"type the new name",IF(AND(L4<>"",L4<>"(decide)",COUNTIF($L$2:$L$1680,L4)>1),"SAME FINAL NAME AS ANOTHER ROW",""))) | N4: 0
A5: 4 | B5: Wire & Cable | C5: bare CU, solid | D5: #8 bare CU, solid | E5: #8 bare solid Copper | F5: wire rule: size/type, metal spelled out at the end | G5: 2 starters | H5: Shipped | I5: Keep proposed | L5: =IF(I5="Cut","",IF(I5="Your call","(decide)",IF(I5="Rename",J5,IF(I5="Keep",IF(D5="",E5,D5),IF(E5="(unchanged)",D5,E5))))) | M5: =IF(AND(I5="Cut",N5>0,K5=""),"USED: say what replaces it (Note)",IF(AND(I5="Rename",J5=""),"type the new name",IF(AND(L5<>"",L5<>"(decide)",COUNTIF($L$2:$L$1680,L5)>1),"SAME FINAL NAME AS ANOTHER ROW",""))) | N5: 2
A6: 5 | B6: Wire & Cable | C6: bare CU, stranded | D6: #10 bare CU, stranded | E6: #10 bare stranded Copper | F6: wire rule: size/type, metal spelled out at the end | G6: — | H6: Shipped | I6: Keep proposed | L6: =IF(I6="Cut","",IF(I6="Your call","(decide)",IF(I6="Rename",J6,IF(I6="Keep",IF(D6="",E6,D6),IF(E6="(unchanged)",D6,E6))))) | M6: =IF(AND(I6="Cut",N6>0,K6=""),"USED: say what replaces it (Note)",IF(AND(I6="Rename",J6=""),"type the new name",IF(AND(L6<>"",L6<>"(decide)",COUNTIF($L$2:$L$1680,L6)>1),"SAME FINAL NAME AS ANOTHER ROW",""))) | N6: 0
A7: 6 | B7: Wire & Cable | C7: bare CU, stranded | D7: #8 bare CU, stranded | E7: #8 bare stranded Copper | F7: wire rule: size/type, metal spelled out at the end | G7: — | H7: Shipped | I7: Keep proposed | L7: =IF(I7="Cut","",IF(I7="Your call","(decide)",IF(I7="Rename",J7,IF(I7="Keep",IF(D7="",E7,D7),IF(E7="(unchanged)",D7,E7))))) | M7: =IF(AND(I7="Cut",N7>0,K7=""),"USED: say what replaces it (Note)",IF(AND(I7="Rename",J7=""),"type the new name",IF(AND(L7<>"",L7<>"(decide)",COUNTIF($L$2:$L$1680,L7)>1),"SAME FINAL NAME AS ANOTHER ROW",""))) | N7: 0
A8: 7 | B8: Wire & Cable | C8: bare CU, stranded | D8: #6 bare CU, stranded | E8: #6 bare stranded Copper | F8: wire rule: size/type, metal spelled out at the end | G8: 2 starters | H8: Shipped | I8: Keep proposed | L8: =IF(I8="Cut","",IF(I8="Your call","(decide)",IF(I8="Rename",J8,IF(I8="Keep",IF(D8="",E8,D8),IF(E8="(unchanged)",D8,E8))))) | M8: =IF(AND(I8="Cut",N8>0,K8=""),"USED: say what replaces it (Note)",IF(AND(I8="Rename",J8=""),"type the new name",IF(AND(L8<>"",L8<>"(decide)",COUNTIF($L$2:$L$1680,L8)>1),"SAME FINAL NAME AS ANOTHER ROW",""))) | N8: 2
A9: 8 | B9: Wire & Cable | C9: bare CU, stranded | D9: #4 bare CU, stranded | E9: #4 bare stranded Copper | F9: wire rule: size/type, metal spelled out at the end | G9: 3 starters | H9: Shipped | I9: Keep proposed | L9: =IF(I9="Cut","",IF(I9="Your call","(decide)",IF(I9="Rename",J9,IF(I9="Keep",IF(D9="",E9,D9),IF(E9="(unchanged)",D9,E9))))) | M9: =IF(AND(I9="Cut",N9>0,K9=""),"USED: say what replaces it (Note)",IF(AND(I9="Rename",J9=""),"type the new name",IF(AND(L9<>"",L9<>"(decide)",COUNTIF($L$2:$L$1680,L9)>1),"SAME FINAL NAME AS ANOTHER ROW",""))) | N9: 3
A10: 9 | B10: Wire & Cable | C10: bare CU, stranded | D10: #2 bare CU, stranded | E10: #2 bare stranded Copper | F10: wire rule: size/type, metal spelled out at the end | G10: — | H10: Shipped | I10: Keep proposed | L10: =IF(I10="Cut","",IF(I10="Your call","(decide)",IF(I10="Rename",J10,IF(I10="Keep",IF(D10="",E10,D10),IF(E10="(unchanged)",D10,E10))))) | M10: =IF(AND(I10="Cut",N10>0,K10=""),"USED: say what replaces it (Note)",IF(AND(I10="Rename",J10=""),"type the new name",IF(AND(L10<>"",L10<>"(decide)",COUNTIF($L$2:$L$1680,L10)>1),"SAME FINAL NAME AS ANOTHER ROW",""))) | N10: 0
A11: 10 | B11: Wire & Cable | C11: bare CU, stranded | D11: #1/0 bare CU, stranded | E11: 1/0 bare stranded Copper | F11: wire rule: size/type, metal spelled out at the end; aughts without "#" | G11: — | H11: Shipped | I11: Keep proposed | L11: =IF(I11="Cut","",IF(I11="Your call","(decide)",IF(I11="Rename",J11,IF(I11="Keep",IF(D11="",E11,D11),IF(E11="(unchanged)",D11,E11))))) | M11: =IF(AND(I11="Cut",N11>0,K11=""),"USED: say what replaces it (Note)",IF(AND(I11="Rename",J11=""),"type the new name",IF(AND(L11<>"",L11<>"(decide)",COUNTIF($L$2:$L$1680,L11)>1),"SAME FINAL NAME AS ANOTHER ROW",""))) | N11: 0
A12: 11 | B12: Wire & Cable | C12: bare CU, stranded | D12: #2/0 bare CU, stranded | E12: 2/0 bare stranded Copper | F12: wire rule: size/type, metal spelled out at the end; aughts without "#" | G12: — | H12: Shipped | I12: Keep proposed | L12: =IF(I12="Cut","",IF(I12="Your call","(decide)",IF(I12="Rename",J12,IF(I12="Keep",IF(D12="",E12,D12),IF(E12="(unchanged)",D12,E12))))) | M12: =IF(AND(I12="Cut",N12>0,K12=""),"USED: say what replaces it (Note)",IF(AND(I12="Rename",J12=""),"type the new name",IF(AND(L12<>"",L12<>"(decide)",COUNTIF($L$2:$L$1680,L12)>1),"SAME FINAL NAME AS ANOTHER ROW",""))) | N12: 0
A13: 12 | B13: Wire & Cable | C13: fire alarm cable | D13: 16-2 fire alarm cable | E13: 16/2 fire alarm cable Copper | F13: wire rule: size/type, metal spelled out at the end | G13: — | H13: Shipped | I13: Keep proposed | L13: =IF(I13="Cut","",IF(I13="Your call","(decide)",IF(I13="Rename",J13,IF(I13="Keep",IF(D13="",E13,D13),IF(E13="(unchanged)",D13,E13))))) | M13: =IF(AND(I13="Cut",N13>0,K13=""),"USED: say what replaces it (Note)",IF(AND(I13="Rename",J13=""),"type the new name",IF(AND(L13<>"",L13<>"(decide)",COUNTIF($L$2:$L$1680,L13)>1),"SAME FINAL NAME AS ANOTHER ROW",""))) | N13: 0
... A109: 108 | B109: Wire & Cable | C109: XHHW AL | D109: 500 kcmil XHHW AL | E109: 500 kcmil XHHW Aluminum | F109: wire rule: size/type, metal spelled out at the end | G109: — | H109: Shipped | I109: Keep proposed | L109: =IF(I109="Cut","",IF(I109="Your call","(decide)",IF(I109="Rename",J109,IF(I109="Keep",IF(D109="",E109,D109),IF(E109="(unchanged)",D109,E109))))) | M109: =IF(AND(I109="Cut",N109>0,K109=""),"USED: say what replaces it (Note)",IF(AND(I109="Rename",J109=""),"type the new name",IF(AND(L109<>"",L109<>"(decide)",COUNTIF($L$2:$L$1680,L109)>1),"SAME FINAL NAME AS ANOTHER ROW",""))) | N109: 0
A110: 109 | B110: Conduit | C110: EMT | D110: 1/2" EMT | E110: (unchanged) | G110: 1 run type | H110: Shipped | I110: Keep | L110: =IF(I110="Cut","",IF(I110="Your call","(decide)",IF(I110="Rename",J110,IF(I110="Keep",IF(D110="",E110,D110),IF(E110="(unchanged)",D110,E110))))) | M110: =IF(AND(I110="Cut",N110>0,K110=""),"USED: say what replaces it (Note)",IF(AND(I110="Rename",J110=""),"type the new name",IF(AND(L110<>"",L110<>"(decide)",COUNTIF($L$2:$L$1680,L110)>1),"SAME FINAL NAME AS ANOTHER ROW",""))) | N110: 1
A111: 110 | B111: Conduit | C111: EMT | D111: 3/4" EMT | E111: (unchanged) | G111: 1 run type | H111: Shipped | I111: Keep | L111: =IF(I111="Cut","",IF(I111="Your call","(decide)",IF(I111="Rename",J111,IF(I111="Keep",IF(D111="",E111,D111),IF(E111="(unchanged)",D111,E111))))) | M111: =IF(AND(I111="Cut",N111>0,K111=""),"USED: say what replaces it (Note)",IF(AND(I111="Rename",J111=""),"type the new name",IF(AND(L111<>"",L111<>"(decide)",COUNTIF($L$2:$L$1680,L111)>1),"SAME FINAL NAME AS ANOTHER ROW",""))) | N111: 1
A112: 111 | B112: Conduit | C112: EMT | D112: 1" EMT | E112: (unchanged) | G112: — | H112: Shipped | I112: Keep | L112: =IF(I112="Cut","",IF(I112="Your call","(decide)",IF(I112="Rename",J112,IF(I112="Keep",IF(D112="",E112,D112),IF(E112="(unchanged)",D112,E112))))) | M112: =IF(AND(I112="Cut",N112>0,K112=""),"USED: say what replaces it (Note)",IF(AND(I112="Rename",J112=""),"type the new name",IF(AND(L112<>"",L112<>"(decide)",COUNTIF($L$2:$L$1680,L112)>1),"SAME FINAL NAME AS ANOTHER ROW",""))) | N112: 0
A113: 112 | B113: Conduit | C113: EMT | D113: 1-1/4" EMT | E113: (unchanged) | G113: — | H113: Shipped | I113: Keep | L113: =IF(I113="Cut","",IF(I113="Your call","(decide)",IF(I113="Rename",J113,IF(I113="Keep",IF(D113="",E113,D113),IF(E113="(unchanged)",D113,E113))))) | M113: =IF(AND(I113="Cut",N113>0,K113=""),"USED: say what replaces it (Note)",IF(AND(I113="Rename",J113=""),"type the new name",IF(AND(L113<>"",L113<>"(decide)",COUNTIF($L$2:$L$1680,L113)>1),"SAME FINAL NAME AS ANOTHER ROW",""))) | N113: 0
A114: 113 | B114: Conduit | C114: EMT | D114: 1-1/2" EMT | E114: (unchanged) | G114: — | H114: Shipped | I114: Keep | L114: =IF(I114="Cut","",IF(I114="Your call","(decide)",IF(I114="Rename",J114,IF(I114="Keep",IF(D114="",E114,D114),IF(E114="(unchanged)",D114,E114))))) | M114: =IF(AND(I114="Cut",N114>0,K114=""),"USED: say what replaces it (Note)",IF(AND(I114="Rename",J114=""),"type the new name",IF(AND(L114<>"",L114<>"(decide)",COUNTIF($L$2:$L$1680,L114)>1),"SAME FINAL NAME AS ANOTHER ROW",""))) | N114: 0
A115: 114 | B115: Conduit | C115: EMT | D115: 2" EMT | E115: (unchanged) | G115: — | H115: Shipped | I115: Keep | L115: =IF(I115="Cut","",IF(I115="Your call","(decide)",IF(I115="Rename",J115,IF(I115="Keep",IF(D115="",E115,D115),IF(E115="(unchanged)",D115,E115))))) | M115: =IF(AND(I115="Cut",N115>0,K115=""),"USED: say what replaces it (Note)",IF(AND(I115="Rename",J115=""),"type the new name",IF(AND(L115<>"",L115<>"(decide)",COUNTIF($L$2:$L$1680,L115)>1),"SAME FINAL NAME AS ANOTHER ROW",""))) | N115: 0
A116: 115 | B116: Conduit | C116: EMT | D116: 2-1/2" EMT | E116: (unchanged) | G116: — | H116: Shipped | I116: Keep | L116: =IF(I116="Cut","",IF(I116="Your call","(decide)",IF(I116="Rename",J116,IF(I116="Keep",IF(D116="",E116,D116),IF(E116="(unchanged)",D116,E116))))) | M116: =IF(AND(I116="Cut",N116>0,K116=""),"USED: say what replaces it (Note)",IF(AND(I116="Rename",J116=""),"type the new name",IF(AND(L116<>"",L116<>"(decide)",COUNTIF($L$2:$L$1680,L116)>1),"SAME FINAL NAME AS ANOTHER ROW",""))) | N116: 0
A117: 116 | B117: Conduit | C117: EMT | D117: 3" EMT | E117: (unchanged) | G117: — | H117: Shipped | I117: Keep | L117: =IF(I117="Cut","",IF(I117="Your call","(decide)",IF(I117="Rename",J117,IF(I117="Keep",IF(D117="",E117,D117),IF(E117="(unchanged)",D117,E117))))) | M117: =IF(AND(I117="Cut",N117>0,K117=""),"USED: say what replaces it (Note)",IF(AND(I117="Rename",J117=""),"type the new name",IF(AND(L117<>"",L117<>"(decide)",COUNTIF($L$2:$L$1680,L117)>1),"SAME FINAL NAME AS ANOTHER ROW",""))) | N117: 0
A118: 117 | B118: Conduit | C118: EMT | D118: 4" EMT | E118: (unchanged) | G118: — | H118: Shipped | I118: Keep | L118: =IF(I118="Cut","",IF(I118="Your call","(decide)",IF(I118="Rename",J118,IF(I118="Keep",IF(D118="",E118,D118),IF(E118="(unchanged)",D118,E118))))) | M118: =IF(AND(I118="Cut",N118>0,K118=""),"USED: say what replaces it (Note)",IF(AND(I118="Rename",J118=""),"type the new name",IF(AND(L118<>"",L118<>"(decide)",COUNTIF($L$2:$L$1680,L118)>1),"SAME FINAL NAME AS ANOTHER ROW",""))) | N118: 0
A119: 118 | B119: Conduit | C119: PVC Sch 40 | D119: 1/2" PVC Sch 40 | E119: (unchanged) | G119: — | H119: Shipped | I119: Keep | L119: =IF(I119="Cut","",IF(I119="Your call","(decide)",IF(I119="Rename",J119,IF(I119="Keep",IF(D119="",E119,D119),IF(E119="(unchanged)",D119,E119))))) | M119: =IF(AND(I119="Cut",N119>0,K119=""),"USED: say what replaces it (Note)",IF(AND(I119="Rename",J119=""),"type the new name",IF(AND(L119<>"",L119<>"(decide)",COUNTIF($L$2:$L$1680,L119)>1),"SAME FINAL NAME AS ANOTHER ROW",""))) | N119: 0
A120: 119 | B120: Conduit | C120: PVC Sch 40 | D120: 3/4" PVC Sch 40 | E120: (unchanged) | G120: — | H120: Shipped | I120: Keep | L120: =IF(I120="Cut","",IF(I120="Your call","(decide)",IF(I120="Rename",J120,IF(I120="Keep",IF(D120="",E120,D120),IF(E120="(unchanged)",D120,E120))))) | M120: =IF(AND(I120="Cut",N120>0,K120=""),"USED: say what replaces it (Note)",IF(AND(I120="Rename",J120=""),"type the new name",IF(AND(L120<>"",L120<>"(decide)",COUNTIF($L$2:$L$1680,L120)>1),"SAME FINAL NAME AS ANOTHER ROW",""))) | N120: 0
A121: 120 | B121: Conduit | C121: PVC Sch 40 | D121: 1" PVC Sch 40 | E121: (unchanged) | G121: — | H121: Shipped | I121: Keep | L121: =IF(I121="Cut","",IF(I121="Your call","(decide)",IF(I121="Rename",J121,IF(I121="Keep",IF(D121="",E121,D121),IF(E121="(unchanged)",D121,E121))))) | M121: =IF(AND(I121="Cut",N121>0,K121=""),"USED: say what replaces it (Note)",IF(AND(I121="Rename",J121=""),"type the new name",IF(AND(L121<>"",L121<>"(decide)",COUNTIF($L$2:$L$1680,L121)>1),"SAME FINAL NAME AS ANOTHER ROW",""))) | N121: 0
... A279: 278 | B279: Conduit Fittings | C279: EMT set-screw coupling | D279: 4" EMT set-screw coupling | E279: (unchanged) | G279: — | H279: Shipped | I279: Keep | L279: =IF(I279="Cut","",IF(I279="Your call","(decide)",IF(I279="Rename",J279,IF(I279="Keep",IF(D279="",E279,D279),IF(E279="(unchanged)",D279,E279))))) | M279: =IF(AND(I279="Cut",N279>0,K279=""),"USED: say what replaces it (Note)",IF(AND(I279="Rename",J279=""),"type the new name",IF(AND(L279<>"",L279<>"(decide)",COUNTIF($L$2:$L$1680,L279)>1),"SAME FINAL NAME AS ANOTHER ROW",""))) | N279: 0
A280: 279 | B280: Conduit Fittings | D280: EMT strap | E280: (unchanged) | G280: — | H280: Shipped | I280: Keep | L280: =IF(I280="Cut","",IF(I280="Your call","(decide)",IF(I280="Rename",J280,IF(I280="Keep",IF(D280="",E280,D280),IF(E280="(unchanged)",D280,E280))))) | M280: =IF(AND(I280="Cut",N280>0,K280=""),"USED: say what replaces it (Note)",IF(AND(I280="Rename",J280=""),"type the new name",IF(AND(L280<>"",L280<>"(decide)",COUNTIF($L$2:$L$1680,L280)>1),"SAME FINAL NAME AS ANOTHER ROW",""))) | N280: 0
A281: 280 | B281: Conduit Fittings | C281: EMT T conduit body | D281: 1/2" EMT T conduit body | E281: (unchanged) | G281: — | H281: Shipped | I281: Keep | L281: =IF(I281="Cut","",IF(I281="Your call","(decide)",IF(I281="Rename",J281,IF(I281="Keep",IF(D281="",E281,D281),IF(E281="(unchanged)",D281,E281))))) | M281: =IF(AND(I281="Cut",N281>0,K281=""),"USED: say what replaces it (Note)",IF(AND(I281="Rename",J281=""),"type the new name",IF(AND(L281<>"",L281<>"(decide)",COUNTIF($L$2:$L$1680,L281)>1),"SAME FINAL NAME AS ANOTHER ROW",""))) | N281: 0
A282: 281 | B282: Conduit Fittings | C282: EMT T conduit body | D282: 3/4" EMT T conduit body | E282: (unchanged) | G282: — | H282: Shipped | I282: Keep | L282: =IF(I282="Cut","",IF(I282="Your call","(decide)",IF(I282="Rename",J282,IF(I282="Keep",IF(D282="",E282,D282),IF(E282="(unchanged)",D282,E282))))) | M282: =IF(AND(I282="Cut",N282>0,K282=""),"USED: say what replaces it (Note)",IF(AND(I282="Rename",J282=""),"type the new name",IF(AND(L282<>"",L282<>"(decide)",COUNTIF($L$2:$L$1680,L282)>1),"SAME FINAL NAME AS ANOTHER ROW",""))) | N282: 0
A283: 282 | B283: Conduit Fittings | C283: EMT T conduit body | D283: 1" EMT T conduit body | E283: (unchanged) | G283: — | H283: Shipped | I283: Keep | L283: =IF(I283="Cut","",IF(I283="Your call","(decide)",IF(I283="Rename",J283,IF(I283="Keep",IF(D283="",E283,D283),IF(E283="(unchanged)",D283,E283))))) | M283: =IF(AND(I283="Cut",N283>0,K283=""),"USED: say what replaces it (Note)",IF(AND(I283="Rename",J283=""),"type the new name",IF(AND(L283<>"",L283<>"(decide)",COUNTIF($L$2:$L$1680,L283)>1),"SAME FINAL NAME AS ANOTHER ROW",""))) | N283: 0
A284: 283 | B284: Conduit Fittings | C284: EMT T conduit body | D284: 1-1/4" EMT T conduit body | E284: (unchanged) | G284: — | H284: Shipped | I284: Keep | L284: =IF(I284="Cut","",IF(I284="Your call","(decide)",IF(I284="Rename",J284,IF(I284="Keep",IF(D284="",E284,D284),IF(E284="(unchanged)",D284,E284))))) | M284: =IF(AND(I284="Cut",N284>0,K284=""),"USED: say what replaces it (Note)",IF(AND(I284="Rename",J284=""),"type the new name",IF(AND(L284<>"",L284<>"(decide)",COUNTIF($L$2:$L$1680,L284)>1),"SAME FINAL NAME AS ANOTHER ROW",""))) | N284: 0
A285: 284 | B285: Conduit Fittings | C285: EMT T conduit body | D285: 1-1/2" EMT T conduit body | E285: (unchanged) | G285: — | H285: Shipped | I285: Keep | L285: =IF(I285="Cut","",IF(I285="Your call","(decide)",IF(I285="Rename",J285,IF(I285="Keep",IF(D285="",E285,D285),IF(E285="(unchanged)",D285,E285))))) | M285: =IF(AND(I285="Cut",N285>0,K285=""),"USED: say what replaces it (Note)",IF(AND(I285="Rename",J285=""),"type the new name",IF(AND(L285<>"",L285<>"(decide)",COUNTIF($L$2:$L$1680,L285)>1),"SAME FINAL NAME AS ANOTHER ROW",""))) | N285: 0
A286: 285 | B286: Conduit Fittings | C286: EMT T conduit body | D286: 2" EMT T conduit body | E286: (unchanged) | G286: — | H286: Shipped | I286: Keep | L286: =IF(I286="Cut","",IF(I286="Your call","(decide)",IF(I286="Rename",J286,IF(I286="Keep",IF(D286="",E286,D286),IF(E286="(unchanged)",D286,E286))))) | M286: =IF(AND(I286="Cut",N286>0,K286=""),"USED: say what replaces it (Note)",IF(AND(I286="Rename",J286=""),"type the new name",IF(AND(L286<>"",L286<>"(decide)",COUNTIF($L$2:$L$1680,L286)>1),"SAME FINAL NAME AS ANOTHER ROW",""))) | N286: 0
A287: 286 | B287: Conduit Fittings | C287: EMT T conduit body | D287: 2-1/2" EMT T conduit body | E287: (unchanged) | G287: — | H287: Shipped | I287: Keep | L287: =IF(I287="Cut","",IF(I287="Your call","(decide)",IF(I287="Rename",J287,IF(I287="Keep",IF(D287="",E287,D287),IF(E287="(unchanged)",D287,E287))))) | M287: =IF(AND(I287="Cut",N287>0,K287=""),"USED: say what replaces it (Note)",IF(AND(I287="Rename",J287=""),"type the new name",IF(AND(L287<>"",L287<>"(decide)",COUNTIF($L$2:$L$1680,L287)>1),"SAME FINAL NAME AS ANOTHER ROW",""))) | N287: 0
A288: 287 | B288: Conduit Fittings | C288: EMT T conduit body | D288: 3" EMT T conduit body | E288: (unchanged) | G288: — | H288: Shipped | I288: Keep | L288: =IF(I288="Cut","",IF(I288="Your call","(decide)",IF(I288="Rename",J288,IF(I288="Keep",IF(D288="",E288,D288),IF(E288="(unchanged)",D288,E288))))) | M288: =IF(AND(I288="Cut",N288>0,K288=""),"USED: say what replaces it (Note)",IF(AND(I288="Rename",J288=""),"type the new name",IF(AND(L288<>"",L288<>"(decide)",COUNTIF($L$2:$L$1680,L288)>1),"SAME FINAL NAME AS ANOTHER ROW",""))) | N288: 0
A289: 288 | B289: Conduit Fittings | C289: EMT T conduit body | D289: 4" EMT T conduit body | E289: (unchanged) | G289: — | H289: Shipped | I289: Keep | L289: =IF(I289="Cut","",IF(I289="Your call","(decide)",IF(I289="Rename",J289,IF(I289="Keep",IF(D289="",E289,D289),IF(E289="(unchanged)",D289,E289))))) | M289: =IF(AND(I289="Cut",N289>0,K289=""),"USED: say what replaces it (Note)",IF(AND(I289="Rename",J289=""),"type the new name",IF(AND(L289<>"",L289<>"(decide)",COUNTIF($L$2:$L$1680,L289)>1),"SAME FINAL NAME AS ANOTHER ROW",""))) | N289: 0
A290: 289 | B290: Conduit Fittings | C290: PVC Sch 40 45-degree elbow | D290: 1/2" PVC Sch 40 45-degree elbow | E290: (unchanged) | G290: — | H290: Shipped | I290: Keep | L290: =IF(I290="Cut","",IF(I290="Your call","(decide)",IF(I290="Rename",J290,IF(I290="Keep",IF(D290="",E290,D290),IF(E290="(unchanged)",D290,E290))))) | M290: =IF(AND(I290="Cut",N290>0,K290=""),"USED: say what replaces it (Note)",IF(AND(I290="Rename",J290=""),"type the new name",IF(AND(L290<>"",L290<>"(decide)",COUNTIF($L$2:$L$1680,L290)>1),"SAME FINAL NAME AS ANOTHER ROW",""))) | N290: 0
A291: 290 | B291: Conduit Fittings | C291: PVC Sch 40 45-degree elbow | D291: 3/4" PVC Sch 40 45-degree elbow | E291: (unchanged) | G291: — | H291: Shipped | I291: Keep | L291: =IF(I291="Cut","",IF(I291="Your call","(decide)",IF(I291="Rename",J291,IF(I291="Keep",IF(D291="",E291,D291),IF(E291="(unchanged)",D291,E291))))) | M291: =IF(AND(I291="Cut",N291>0,K291=""),"USED: say what replaces it (Note)",IF(AND(I291="Rename",J291=""),"type the new name",IF(AND(L291<>"",L291<>"(decide)",COUNTIF($L$2:$L$1680,L291)>1),"SAME FINAL NAME AS ANOTHER ROW",""))) | N291: 0
A292: 291 | B292: Conduit Fittings | C292: PVC Sch 40 45-degree elbow | D292: 1" PVC Sch 40 45-degree elbow | E292: (unchanged) | G292: — | H292: Shipped | I292: Keep | L292: =IF(I292="Cut","",IF(I292="Your call","(decide)",IF(I292="Rename",J292,IF(I292="Keep",IF(D292="",E292,D292),IF(E292="(unchanged)",D292,E292))))) | M292: =IF(AND(I292="Cut",N292>0,K292=""),"USED: say what replaces it (Note)",IF(AND(I292="Rename",J292=""),"type the new name",IF(AND(L292<>"",L292<>"(decide)",COUNTIF($L$2:$L$1680,L292)>1),"SAME FINAL NAME AS ANOTHER ROW",""))) | N292: 0
...

Sheet Missing
A1: Source | B1: Category | C1: Item | D1: Why it is listed | E1: Decision | F1: Your name | G1: Note
A2: Starter | C2: Surface raceway, 10 ft | D2: needed by "Surface raceway receptacle (block wall)" (DV34), which is held until it exists | E2: Skip | G2: Covered by the waiting Surface Raceway rows (base/cover 500 and 700 series, 1500 series). DV34's recipe must be pointed at those names when they are added.
A3: Starter | C3: Surface raceway device box | D3: needed by "Surface raceway receptacle (block wall)" (DV34), which is held until it exists | E3: Skip | G3: Covered by the waiting "Raceway device box, 1-gang".
A4: Starter | C4: Surface raceway cover plate | D4: needed by "Surface raceway receptacle (block wall)" (DV34), which is held until it exists | E4: Skip | G4: A standard wall plate fits the raceway device box.
A5: Starter | C5: Surface raceway entrance fitting | D5: needed by "Surface raceway receptacle (block wall)" (DV34), which is held until it exists | E5: Skip | G5: Covered by the waiting "Raceway entrance end fitting".
A6: Size gap | B6: Wire & Cable | C6: #3 XHHW Aluminum | D6: XHHW AL comes in sizes either side of #3 | E6: Add | G6: Owner 2026-10-07: add it back — same style as the other aluminum sizes.
A7: Size gap | B7: Wire & Cable | C7: #3 bare stranded Copper | D7: bare CU, stranded comes in sizes either side of #3 | E7: Skip | G7: #4 and #2 bare are the grounding sizes used.
A8: Size gap | B8: Wire & Cable | C8: #1 bare stranded Copper | D8: bare CU, stranded comes in sizes either side of #1 | E8: Skip | G8: Rare on small commercial work.
A9: Size gap | B9: Conduit Fittings | C9: 3-1/2" EMT 90-degree elbow | D9: EMT 90-degree elbow comes in sizes either side of 3-1/2" | E9: Add | G9: 3-1/2" EMT is being added (pricing sheet); a run needs its elbows.
A10: Size gap | B10: Conduit Fittings | C10: 3-1/2" EMT 45-degree elbow | D10: EMT 45-degree elbow comes in sizes either side of 3-1/2" | E10: Add | G10: As the 90.
A11: Size gap | B11: Conduit Fittings | C11: 3-1/2" EMT LB conduit body | D11: EMT LB conduit body comes in sizes either side of 3-1/2" | E11: Skip | G11: The waiting "Conduit body, 3-1/2" LB" already adds it.
A12: Size gap | B12: Conduit Fittings | C12: 3-1/2" EMT T conduit body | D12: EMT T conduit body comes in sizes either side of 3-1/2" | E12: Skip | G12: 3-1/2" in a type that is not being added (Sch 80, rigid, IMC, compression/raintight, other conduit bodies, 45 sweeps, weatherheads), a sized nail plate (not sold by trade size), or a 5" duct part (4" and 6" are the sizes used).
A13: Size gap | B13: Conduit Fittings | C13: 3-1/2" EMT LL conduit body | D13: EMT LL conduit body comes in sizes either side of 3-1/2" | E13: Skip | G13: 3-1/2" in a type that is not being added (Sch 80, rigid, IMC, compression/raintight, other conduit bodies, 45 sweeps, weatherheads), a sized nail plate (not sold by trade size), or a 5" duct part (4" and 6" are the sizes used).
A14: Size gap | B14: Conduit Fittings | C14: 3-1/2" EMT LR conduit body | D14: EMT LR conduit body comes in sizes either side of 3-1/2" | E14: Skip | G14: 3-1/2" in a type that is not being added (Sch 80, rigid, IMC, compression/raintight, other conduit bodies, 45 sweeps, weatherheads), a sized nail plate (not sold by trade size), or a 5" duct part (4" and 6" are the sizes used).
A15: Size gap | B15: Conduit Fittings | C15: 3-1/2" EMT C conduit body | D15: EMT C conduit body comes in sizes either side of 3-1/2" | E15: Skip | G15: 3-1/2" in a type that is not being added (Sch 80, rigid, IMC, compression/raintight, other conduit bodies, 45 sweeps, weatherheads), a sized nail plate (not sold by trade size), or a 5" duct part (4" and 6" are the sizes used).
A16: Size gap | B16: Conduit Fittings | C16: 3-1/2" EMT set-screw connector | D16: EMT set-screw connector comes in sizes either side of 3-1/2" | E16: Skip | G16: The waiting "3-1/2" EMT connector" already adds it.
A17: Size gap | B17: Conduit Fittings | C17: 3-1/2" EMT set-screw coupling | D17: EMT set-screw coupling comes in sizes either side of 3-1/2" | E17: Skip | G17: The waiting "3-1/2" EMT coupling" already adds it.
... A86: Size gap | B86: Equipment & Appliances | C86: 5" insulated flex duct | D86: insulated flex duct comes in sizes either side of 5" | E86: Skip | G86: 3-1/2" in a type that is not being added (Sch 80, rigid, IMC, compression/raintight, other conduit bodies, 45 sweeps, weatherheads), a sized nail plate (not sold by trade size), or a 5" duct part (4" and 6" are the sizes used).
A87: Typical job | B87: Wire & Cable | C87: 12/2 MC cable with 16/2 dimming | D87: lighting retrofit: 0-10V fixtures are fed with MC carrying a dimming pair | E87: Add
A88: Typical job | B88: Wire & Cable | C88: 12/2 MC-AP cable | D88: small office TI: aluminum-armor MC with a bonding wire is the common TI cable | E88: Add
A89: Typical job | B89: Wire & Cable | C89: 18/2 shielded fire alarm cable, FPLP | D89: small office TI: plenum fire-alarm cable above lay-in ceilings (14-2 and 16-2 are listed, 18/2 is not) | E89: Add
A90: Typical job | B90: Low Voltage | C90: Cat6 plenum cable | D90: small office TI: data drops above a return-air ceiling must be plenum (CMP); plain Cat6 only lists "plenum" as a search word | E90: Add
A91: Typical job | B91: Conduit Fittings | C91: 1/2" EMT insulated set-screw connector | D91: small office TI: insulated-throat connectors are spec'd on most TI jobs | E91: Add
A92: Typical job | B92: Conduit Fittings | C92: 1/2" EMT to FMC transition coupling | D92: small office TI: EMT drops changing to flex at the fixture | E92: Add
A93: Typical job | B93: Conduit | C93: 3/8" FMC (reduced wall) | D93: lighting retrofit: 3/8" flex is the usual fixture whip conduit | E93: Add
A94: Typical job | B94: Conduit Fittings | C94: 1/2" liquidtight 90-degree connector | D94: service upgrade: rooftop unit and condenser whips turn 90° at the unit | E94: Add
A95: Typical job | B95: Conduit Fittings | C95: 1/2" PVC female adapter | D95: service upgrade: PVC to a threaded fitting | E95: Add
A96: Typical job | B96: Conduit Fittings | C96: 1/2" PVC expansion fitting | D96: service upgrade: exposed outdoor PVC runs need expansion fittings | E96: Add
A97: Typical job | B97: Conduit Fittings | C97: 1/2" EMT offset connector | D97: Dollar Tree / retail retrofit: surface EMT into a box without bending an offset | E97: Add
A98: Typical job | B98: Strut & Supports | C98: T-bar box hanger | D98: small office TI: boxes in a lay-in grid hang from the T-bar (a grid clip and a fan bar hanger are listed, a box hanger is not) | E98: Add
... A101: Owner | B101: Panels | C101: 320A meter base | D101: Owner 2026-10-07: Track B's drafted recipe GR3 (320A/400A residential service) — the class-320 meter base with two 200A main breakers; 400A meter base stands in until it exists. | E101: Add
A102: Your row
A103: Your row
A104: Your row
A105: Your row
A106: Your row
A107: Your row
A108: Your row
A109: Your row
A110: Your row
...

Sheet Possible duplicates
A1: A | B1: A is | C1: A used by | D1: B | E1: B is | F1: B used by | G1: Why they look the same | H1: Decision | I1: Note
A2: 2" mast roof flashing | B2: Shipped | C2: 1 starter | D2: Mast roof flashing | E2: New — not in catalog yet | F2: — | G2: same words; the new row names no size, the shipped one is 2" | H2: Same - keep A | I2: The new row is the shipped 2" part with its size left off.
A3: 2" riser strap | B3: Shipped | C3: 1 starter | D3: Riser strap, 2" | E3: New — not in catalog yet | F3: — | G3: same size and the same words (2"), spelled or ordered differently | H3: Same - keep A | I3: Owner, 2026-10-07.
A4: 4" wafer LED downlight | B4: Shipped | C4: 1 starter | D4: 4" canless LED downlight | E4: New — not in catalog yet | F4: — | G4: same size and the same words (4"), spelled or ordered differently | H4: Same - keep A | I4: Owner 2026-10-07: 4" and 6" as separate canless wafers. The shipped 4" is renamed "4" canless wafer LED downlight" (same row, starter LT8 follows) and is this part.
A5: 5"/6" wafer LED downlight | B5: Shipped | C5: 1 starter | D5: 5" canless LED downlight | E5: New — not in catalog yet | F5: — | G5: same words and size; one name also states 6" | H5: Not the same | I5: Owner 2026-10-07: do not fold. The shipped 5"/6" becomes the 6" item; a 5" is not used (this new row is not added — Review: Cut).
A6: 5"/6" wafer LED downlight | B6: Shipped | C6: 1 starter | D6: 6" canless LED downlight | E6: New — not in catalog yet | F6: — | G6: same words and size; one name also states 5" | H6: Same - keep A | I6: The shipped 5"/6" is RENAMED into "6" canless wafer LED downlight" (same row, so starter LT7 keeps pricing from it) — this new row would be a second 6".
A7: Ground rod, 10 ft | B7: Shipped | C7: — | D7: Ground rod, 3/4" x 10 ft | E7: Shipped | F7: — | G7: same words and size; one name also states 3/4" | H7: Not the same | I7: Owner 2026-10-07: three rods. 5/8" x 8 ft is the usual one; the plain 10 ft is renamed "Ground rod, 5/8" x 10 ft"; 3/4" x 10 ft stays.
A9: How these were found: 6 pair(s) from 1679 rows, matched on size, type, material and key words with spellings folded (1-pole = single pole = 1P; set screw = SS; CU = copper) and search words — and kept apart when a key word differs (set screw vs compression, 1-pole vs 2-pole, copper vs aluminum, EMT vs PVC, a different size or amperage).

Sheet Questions
A1: # | B1: Question | C1: Recommended | D1: Your answer | E1: Note
A2: Q2 | B2: SER cable: keep the full conductor set (e.g. 4/0-4/0-4/0-2/0) in the description and as a search word, with a check that no two SER rows share size + metal? And keep the two 3-conductor rows' full names? | C2: Yes | D2: Yes
A3: Q2d | B3: "3/4 MC cable Copper" (a #3 four-wire) reads like 3/4 inch. Write it "#3/4 MC cable Copper" instead? | C3: Yes, #3/4 | D3: Yes | E3: Use "#3/4" (owner).
A4: Q3 | B4: Once shipped prices are no longer $0: should a bid line priced from an example price SAY so on the bid and the quote, until you change that material's price? | C4: Yes | D4: Yes on my bid screen, not on the customer quote. Warn me before printing instead. | E4: Recorded: the tag shows on the bid screen only; the customer quote never shows it; printing warns first.
A5: Q4 | B5: Add "Copper" to the end of low-voltage cable names (not fiber)? Copper-clad (CCA) rows only if wanted. | C5: Yes | D5: Yes
A6: Q5 | B6: Hide the supplier-import button until its review screen (with undo) exists? Today an import writes at once and cannot be undone except by hand. | C6: Yes | D6: Yes

Sheet Counts
A1: Category | B1: Keep proposed | C1: Keep | D1: Rename | E1: Cut | F1: Add | G1: Your call
A2: Wire & Cable | B2: =COUNTIFS(Review!$B$2:$B$1680,$A2,Review!$I$2:$I$1680,"Keep proposed") | C2: =COUNTIFS(Review!$B$2:$B$1680,$A2,Review!$I$2:$I$1680,"Keep") | D2: =COUNTIFS(Review!$B$2:$B$1680,$A2,Review!$I$2:$I$1680,"Rename") | E2: =COUNTIFS(Review!$B$2:$B$1680,$A2,Review!$I$2:$I$1680,"Cut") | F2: =COUNTIFS(Review!$B$2:$B$1680,$A2,Review!$I$2:$I$1680,"Add") | G2: =COUNTIFS(Review!$B$2:$B$1680,$A2,Review!$I$2:$I$1680,"Your call")
A3: Conduit | B3: =COUNTIFS(Review!$B$2:$B$1680,$A3,Review!$I$2:$I$1680,"Keep proposed") | C3: =COUNTIFS(Review!$B$2:$B$1680,$A3,Review!$I$2:$I$1680,"Keep") | D3: =COUNTIFS(Review!$B$2:$B$1680,$A3,Review!$I$2:$I$1680,"Rename") | E3: =COUNTIFS(Review!$B$2:$B$1680,$A3,Review!$I$2:$I$1680,"Cut") | F3: =COUNTIFS(Review!$B$2:$B$1680,$A3,Review!$I$2:$I$1680,"Add") | G3: =COUNTIFS(Review!$B$2:$B$1680,$A3,Review!$I$2:$I$1680,"Your call")
A4: Conduit Fittings | B4: =COUNTIFS(Review!$B$2:$B$1680,$A4,Review!$I$2:$I$1680,"Keep proposed") | C4: =COUNTIFS(Review!$B$2:$B$1680,$A4,Review!$I$2:$I$1680,"Keep") | D4: =COUNTIFS(Review!$B$2:$B$1680,$A4,Review!$I$2:$I$1680,"Rename") | E4: =COUNTIFS(Review!$B$2:$B$1680,$A4,Review!$I$2:$I$1680,"Cut") | F4: =COUNTIFS(Review!$B$2:$B$1680,$A4,Review!$I$2:$I$1680,"Add") | G4: =COUNTIFS(Review!$B$2:$B$1680,$A4,Review!$I$2:$I$1680,"Your call")
A5: Boxes | B5: =COUNTIFS(Review!$B$2:$B$1680,$A5,Review!$I$2:$I$1680,"Keep proposed") | C5: =COUNTIFS(Review!$B$2:$B$1680,$A5,Review!$I$2:$I$1680,"Keep") | D5: =COUNTIFS(Review!$B$2:$B$1680,$A5,Review!$I$2:$I$1680,"Rename") | E5: =COUNTIFS(Review!$B$2:$B$1680,$A5,Review!$I$2:$I$1680,"Cut") | F5: =COUNTIFS(Review!$B$2:$B$1680,$A5,Review!$I$2:$I$1680,"Add") | G5: =COUNTIFS(Review!$B$2:$B$1680,$A5,Review!$I$2:$I$1680,"Your call")
A6: Receptacles | B6: =COUNTIFS(Review!$B$2:$B$1680,$A6,Review!$I$2:$I$1680,"Keep proposed") | C6: =COUNTIFS(Review!$B$2:$B$1680,$A6,Review!$I$2:$I$1680,"Keep") | D6: =COUNTIFS(Review!$B$2:$B$1680,$A6,Review!$I$2:$I$1680,"Rename") | E6: =COUNTIFS(Review!$B$2:$B$1680,$A6,Review!$I$2:$I$1680,"Cut") | F6: =COUNTIFS(Review!$B$2:$B$1680,$A6,Review!$I$2:$I$1680,"Add") | G6: =COUNTIFS(Review!$B$2:$B$1680,$A6,Review!$I$2:$I$1680,"Your call")
A7: Switches | B7: =COUNTIFS(Review!$B$2:$B$1680,$A7,Review!$I$2:$I$1680,"Keep proposed") | C7: =COUNTIFS(Review!$B$2:$B$1680,$A7,Review!$I$2:$I$1680,"Keep") | D7: =COUNTIFS(Review!$B$2:$B$1680,$A7,Review!$I$2:$I$1680,"Rename") | E7: =COUNTIFS(Review!$B$2:$B$1680,$A7,Review!$I$2:$I$1680,"Cut") | F7: =COUNTIFS(Review!$B$2:$B$1680,$A7,Review!$I$2:$I$1680,"Add") | G7: =COUNTIFS(Review!$B$2:$B$1680,$A7,Review!$I$2:$I$1680,"Your call")
A8: Wall Plates & Misc | B8: =COUNTIFS(Review!$B$2:$B$1680,$A8,Review!$I$2:$I$1680,"Keep proposed") | C8: =COUNTIFS(Review!$B$2:$B$1680,$A8,Review!$I$2:$I$1680,"Keep") | D8: =COUNTIFS(Review!$B$2:$B$1680,$A8,Review!$I$2:$I$1680,"Rename") | E8: =COUNTIFS(Review!$B$2:$B$1680,$A8,Review!$I$2:$I$1680,"Cut") | F8: =COUNTIFS(Review!$B$2:$B$1680,$A8,Review!$I$2:$I$1680,"Add") | G8: =COUNTIFS(Review!$B$2:$B$1680,$A8,Review!$I$2:$I$1680,"Your call")
A9: Panels | B9: =COUNTIFS(Review!$B$2:$B$1680,$A9,Review!$I$2:$I$1680,"Keep proposed") | C9: =COUNTIFS(Review!$B$2:$B$1680,$A9,Review!$I$2:$I$1680,"Keep") | D9: =COUNTIFS(Review!$B$2:$B$1680,$A9,Review!$I$2:$I$1680,"Rename") | E9: =COUNTIFS(Review!$B$2:$B$1680,$A9,Review!$I$2:$I$1680,"Cut") | F9: =COUNTIFS(Review!$B$2:$B$1680,$A9,Review!$I$2:$I$1680,"Add") | G9: =COUNTIFS(Review!$B$2:$B$1680,$A9,Review!$I$2:$I$1680,"Your call")
A10: Breakers | B10: =COUNTIFS(Review!$B$2:$B$1680,$A10,Review!$I$2:$I$1680,"Keep proposed") | C10: =COUNTIFS(Review!$B$2:$B$1680,$A10,Review!$I$2:$I$1680,"Keep") | D10: =COUNTIFS(Review!$B$2:$B$1680,$A10,Review!$I$2:$I$1680,"Rename") | E10: =COUNTIFS(Review!$B$2:$B$1680,$A10,Review!$I$2:$I$1680,"Cut") | F10: =COUNTIFS(Review!$B$2:$B$1680,$A10,Review!$I$2:$I$1680,"Add") | G10: =COUNTIFS(Review!$B$2:$B$1680,$A10,Review!$I$2:$I$1680,"Your call")
A11: Lighting Hardware | B11: =COUNTIFS(Review!$B$2:$B$1680,$A11,Review!$I$2:$I$1680,"Keep proposed") | C11: =COUNTIFS(Review!$B$2:$B$1680,$A11,Review!$I$2:$I$1680,"Keep") | D11: =COUNTIFS(Review!$B$2:$B$1680,$A11,Review!$I$2:$I$1680,"Rename") | E11: =COUNTIFS(Review!$B$2:$B$1680,$A11,Review!$I$2:$I$1680,"Cut") | F11: =COUNTIFS(Review!$B$2:$B$1680,$A11,Review!$I$2:$I$1680,"Add") | G11: =COUNTIFS(Review!$B$2:$B$1680,$A11,Review!$I$2:$I$1680,"Your call")
A12: Grounding & Bonding | B12: =COUNTIFS(Review!$B$2:$B$1680,$A12,Review!$I$2:$I$1680,"Keep proposed") | C12: =COUNTIFS(Review!$B$2:$B$1680,$A12,Review!$I$2:$I$1680,"Keep") | D12: =COUNTIFS(Review!$B$2:$B$1680,$A12,Review!$I$2:$I$1680,"Rename") | E12: =COUNTIFS(Review!$B$2:$B$1680,$A12,Review!$I$2:$I$1680,"Cut") | F12: =COUNTIFS(Review!$B$2:$B$1680,$A12,Review!$I$2:$I$1680,"Add") | G12: =COUNTIFS(Review!$B$2:$B$1680,$A12,Review!$I$2:$I$1680,"Your call")
A13: Life Safety | B13: =COUNTIFS(Review!$B$2:$B$1680,$A13,Review!$I$2:$I$1680,"Keep proposed") | C13: =COUNTIFS(Review!$B$2:$B$1680,$A13,Review!$I$2:$I$1680,"Keep") | D13: =COUNTIFS(Review!$B$2:$B$1680,$A13,Review!$I$2:$I$1680,"Rename") | E13: =COUNTIFS(Review!$B$2:$B$1680,$A13,Review!$I$2:$I$1680,"Cut") | F13: =COUNTIFS(Review!$B$2:$B$1680,$A13,Review!$I$2:$I$1680,"Add") | G13: =COUNTIFS(Review!$B$2:$B$1680,$A13,Review!$I$2:$I$1680,"Your call")
... A23: Service Entrance | B23: =COUNTIFS(Review!$B$2:$B$1680,$A23,Review!$I$2:$I$1680,"Keep proposed") | C23: =COUNTIFS(Review!$B$2:$B$1680,$A23,Review!$I$2:$I$1680,"Keep") | D23: =COUNTIFS(Review!$B$2:$B$1680,$A23,Review!$I$2:$I$1680,"Rename") | E23: =COUNTIFS(Review!$B$2:$B$1680,$A23,Review!$I$2:$I$1680,"Cut") | F23: =COUNTIFS(Review!$B$2:$B$1680,$A23,Review!$I$2:$I$1680,"Add") | G23: =COUNTIFS(Review!$B$2:$B$1680,$A23,Review!$I$2:$I$1680,"Your call")
A24: Total | B24: =COUNTIF(Review!$I$2:$I$1680,"Keep proposed") | C24: =COUNTIF(Review!$I$2:$I$1680,"Keep") | D24: =COUNTIF(Review!$I$2:$I$1680,"Rename") | E24: =COUNTIF(Review!$I$2:$I$1680,"Cut") | F24: =COUNTIF(Review!$I$2:$I$1680,"Add") | G24: =COUNTIF(Review!$I$2:$I$1680,"Your call")
A26: Rows with the same final name (must be 0) | B26: =COUNTIF(Review!$M$2:$M$1680,"SAME FINAL NAME*")
A27: Cuts a starter still uses, no replacement named (must be 0) | B27: =COUNTIF(Review!$M$2:$M$1680,"USED*")
A28: Rows still 'Your call' (must be 0) | B28: =COUNTIF(Review!$I$2:$I$1680,"Your call")
A29: Possible duplicates not decided (must be 0) | B29: =6-COUNTIF('Possible duplicates'!$H$2:$H$7,"?*")
